<?xml version="1.0" ?>
<!-- =================================================================================== -->
<!-- |    This document was autogenerated by xacro from my_robot_arm.xacro             | -->
<!-- |    EDITING THIS FILE BY HAND IS NOT RECOMMENDED                                 | -->
<!-- =================================================================================== -->
<robot name="my_robot_arm">
  <material name="red">
    <color rgba="1.0 0.0 0.0 1"/>
  </material>
  <!-- <xacro:include filename="$(find my_box_bot_description)/urdf/box_bot.gazebo.xacro" /> -->
  <link name="base_link">
    </link>
  <link name="robot_stand">
    <visual>
      <origin rpy="0 0 0" xyz="0 0 0"/>
      <geometry>
        <box size="0.4 0.4 0.7"/>
      </geometry>
      <material name="red"/>
    </visual>
    <collision>
      <origin rpy="0 0 0" xyz="0 0 0"/>
      <geometry>
        <box size="0.4 0.4 0.7"/>
      </geometry>
    </collision>
    <inertial>
      <origin rpy="0 0 0" xyz="0 0 0"/>
      <mass value="{arm_mass}"/>
      <inertia ixx="7.679324894514766e-07" ixy="0" ixz="0" iyy="7.679324894514766e-07" iyz="0" izz="3.780590717299578e-07"/>
    </inertial>
  </link>
  <link name="first_arm">
    <visual>
      <origin rpy="0 0 0" xyz="0 0 0"/>
      <geometry>
        <box size="0.075 0.075 0.4"/>
      </geometry>
      <material name="red"/>
    </visual>
    <collision>
      <origin rpy="0 0 0" xyz="0 0 0"/>
      <geometry>
        <box size="0.075 0.075 0.4"/>
      </geometry>
    </collision>
    <inertial>
      <origin rpy="0 0 0" xyz="0 0 0"/>
      <mass value="{arm_mass}"/>
      <inertia ixx="3.930973101265823e-09" ixy="0" ixz="0" iyy="3.930973101265823e-09" iyz="0" izz="2.6700949367088605e-10"/>
    </inertial>
  </link>
  <link name="second_arm">
    <visual>
      <origin rpy="0 0 0" xyz="0 0 0"/>
      <geometry>
        <box size="0.075 0.075 0.3"/>
      </geometry>
      <material name="red"/>
    </visual>
    <collision>
      <origin rpy="0 0 0" xyz="0 0 0"/>
      <geometry>
        <box size="0.075 0.075 0.3"/>
      </geometry>
    </collision>
    <inertial>
      <origin rpy="0 0 0" xyz="0 0 0"/>
      <mass value="{arm_mass}"/>
      <inertia ixx="1.7021855221518986e-09" ixy="0" ixz="0" iyy="1.7021855221518986e-09" iyz="0" izz="2.0025712025316453e-10"/>
    </inertial>
  </link>
  <link name="third_arm">
    <visual>
      <origin rpy="0 0 0" xyz="0 0 0"/>
      <geometry>
        <box size="0.075 0.075 0.1"/>
      </geometry>
      <material name="red"/>
    </visual>
    <collision>
      <origin rpy="0 0 0" xyz="0 0 0"/>
      <geometry>
        <box size="0.075 0.075 0.1"/>
      </geometry>
    </collision>
    <inertial>
      <origin rpy="0 0 0" xyz="0 0 0"/>
      <mass value="{arm_mass}"/>
      <inertia ixx="9.271162974683543e-11" ixy="0" ixz="0" iyy="9.271162974683543e-11" iyz="0" izz="6.675237341772151e-11"/>
    </inertial>
  </link>
  <link name="waist_link">
    <visual>
      <origin rpy="0 0 0" xyz="0 0 0"/>
      <geometry>
        <cylinder length="0.1" radius="0.1"/>
      </geometry>
      <material name="red"/>
    </visual>
    <collision>
      <origin rpy="0 0 0" xyz="0 0 0"/>
      <geometry>
        <cylinder length="0.1" radius="0.1"/>
      </geometry>
    </collision>
    <inertial>
      <origin rpy="0 0 0" xyz="0 0 0"/>
      <mass value="3.976582278481013e-07"/>
      <inertia ixx="6.62763713080169e-10" ixy="0" ixz="0" iyy="6.62763713080169e-10" iyz="0" izz="3.313818565400845e-10"/>
    </inertial>
  </link>
  <link name="shoulder_link">
    <visual>
      <origin rpy="0 1.5707 1.5707" xyz="0 0 0"/>
      <geometry>
        <cylinder length="0.1" radius="0.05"/>
      </geometry>
      <material name="red"/>
    </visual>
    <collision>
      <origin rpy="0 1.5707 1.5707" xyz="0 0 0"/>
      <geometry>
        <cylinder length="0.1" radius="0.05"/>
      </geometry>
    </collision>
    <inertial>
      <origin rpy="0 0 0" xyz="0 0 0"/>
      <mass value="9.941455696202533e-08"/>
      <inertia ixx="1.035568301687764e-10" ixy="0" ixz="0" iyy="1.035568301687764e-10" iyz="0" izz="2.0711366033755282e-11"/>
    </inertial>
  </link>
  <link name="elbow_link">
    <visual>
      <origin rpy="0 1.5707 1.5707" xyz="0 0 0"/>
      <geometry>
        <cylinder length="0.1" radius="0.05"/>
      </geometry>
      <material name="red"/>
    </visual>
    <collision>
      <origin rpy="0 1.5707 1.5707" xyz="0 0 0"/>
      <geometry>
        <cylinder length="0.1" radius="0.05"/>
      </geometry>
    </collision>
    <inertial>
      <origin rpy="0 0 0" xyz="0 0 0"/>
      <mass value="9.941455696202533e-08"/>
      <inertia ixx="1.035568301687764e-10" ixy="0" ixz="0" iyy="1.035568301687764e-10" iyz="0" izz="2.0711366033755282e-11"/>
    </inertial>
  </link>
  <link name="wrist_link">
    <visual>
      <origin rpy="0 1.5707 1.5707" xyz="0 0 0"/>
      <geometry>
        <cylinder length="0.1" radius="0.05"/>
      </geometry>
      <material name="red"/>
    </visual>
    <collision>
      <origin rpy="0 1.5707 1.5707" xyz="0 0 0"/>
      <geometry>
        <cylinder length="0.1" radius="0.05"/>
      </geometry>
    </collision>
    <inertial>
      <origin rpy="0 0 0" xyz="0 0 0"/>
      <mass value="9.941455696202533e-08"/>
      <inertia ixx="1.035568301687764e-10" ixy="0" ixz="0" iyy="1.035568301687764e-10" iyz="0" izz="2.0711366033755282e-11"/>
    </inertial>
  </link>
  <joint name="base_link_joint" type="fixed">
    <origin rpy="0 0 0" xyz="0 0 0"/>
    <parent link="base_link"/>
    <child link="robot_stand"/>
  </joint>
  <joint name="waist_stand_robot_joint" type="continuous">
    <origin rpy="0 0 0" xyz="0 0 0.35"/>
    <child link="waist_link"/>
    <parent link="robot_stand"/>
    <axis rpy="0 0 0" xyz="0 0 1"/>
    <limit effort="10000" velocity="1000"/>
    <joint_properties damping="1.0" friction="1.0"/>
  </joint>
  <joint name="shoulder_waist_joint" type="continuous">
    <origin rpy="0 0 0" xyz="0 0 0.1"/>
    <child link="shoulder_link"/>
    <parent link="waist_link"/>
    <axis rpy="0 0 0" xyz="0 1 0"/>
    <limit effort="10000" velocity="1000"/>
    <joint_properties damping="1.0" friction="1.0"/>
  </joint>
  <joint name="first_arm_shoulder_joint" type="fixed">
    <origin rpy="0 0 0" xyz="0 0 0.05"/>
    <parent link="shoulder_link"/>
    <child link="first_arm"/>
  </joint>
  <joint name="elbow_first_arm_joint" type="continuous">
    <origin rpy="0 0 0" xyz="0 0 0.2"/>
    <child link="elbow_link"/>
    <parent link="first_arm"/>
    <axis rpy="0 0 0" xyz="0 1 0"/>
    <limit effort="10000" velocity="1000"/>
    <joint_properties damping="1.0" friction="1.0"/>
  </joint>
  <joint name="second_arm_elbow_joint" type="fixed">
    <origin rpy="0 0 0" xyz="0 0 0.05"/>
    <parent link="elbow_link"/>
    <child link="second_arm"/>
  </joint>
  <joint name="wrist_second_arm_joint" type="continuous">
    <origin rpy="0 0 0" xyz="0 0 0.15"/>
    <child link="wrist_link"/>
    <parent link="second_arm"/>
    <axis rpy="0 0 0" xyz="0 1 0"/>
    <limit effort="10000" velocity="1000"/>
    <joint_properties damping="1.0" friction="1.0"/>
  </joint>
  <joint name="third_arm_wrist_joint" type="fixed">
    <origin rpy="0 0 0" xyz="0 0 0.05"/>
    <parent link="wrist_link"/>
    <child link="third_arm"/>
  </joint>
</robot>
