<?xml version="1.0" ?>
<!-- =================================================================================== -->
<!-- |    This document was autogenerated by xacro from my_robot_arm.xacro             | -->
<!-- |    EDITING THIS FILE BY HAND IS NOT RECOMMENDED                                 | -->
<!-- =================================================================================== -->
<robot name="my_robot_arm">
  <material name="blue">
    <color rgba="0.0 0.0 1.0 1"/>
  </material>
  <material name="green">
    <color rgba="0.0 0.5 0.0 1"/>
  </material>
  <material name="green_light">
    <color rgba="0.0 1.0 0.0 1"/>
  </material>
  <material name="black">
    <color rgba="0.0 0.0 0.0 1"/>
  </material>
  <!-- <xacro:include filename="$(find my_box_bot_description)/urdf/box_bot.gazebo.xacro" /> -->
  <link name="robot_stand">
    <visual>
      <origin rpy="0 0 0" xyz="0 0 0"/>
      <geometry>
        <box size="0.4 0.4 0.7"/>
      </geometry>
      <material name="black"/>
    </visual>
    <collision>
      <origin rpy="0 0 0" xyz="0 0 0"/>
      <geometry>
        <box size="0.4 0.4 0.7"/>
      </geometry>
    </collision>
    <inertial>
      <origin rpy="0 0 0" xyz="0 0 0"/>
      <mass value="1.4177215189873416e-05"/>
      <inertia ixx="7.679324894514766e-07" ixy="0" ixz="0" iyy="7.679324894514766e-07" iyz="0" izz="3.780590717299578e-07"/>
    </inertial>
  </link>
  <link name="first_arm">
    <visual>
      <origin rpy="0 0 0" xyz="0 0 0.16"/>
      <geometry>
        <box size="0.06 0.06 0.32"/>
      </geometry>
      <material name="blue"/>
    </visual>
    <collision>
      <origin rpy="0 0 0" xyz="0 0 0.16"/>
      <geometry>
        <box size="0.06 0.06 0.32"/>
      </geometry>
    </collision>
    <inertial>
      <origin rpy="0 0 0" xyz="0 0 0"/>
      <mass value="1.4582278481012656e-07"/>
      <inertia ixx="1.2881012658227846e-09" ixy="0" ixz="0" iyy="1.2881012658227846e-09" iyz="0" izz="8.749367088607594e-11"/>
    </inertial>
  </link>
  <link name="second_arm">
    <visual>
      <origin rpy="0 0 0" xyz="0 0 0.11"/>
      <geometry>
        <box size="0.06 0.06 0.22"/>
      </geometry>
      <material name="blue"/>
    </visual>
    <collision>
      <origin rpy="0 0 0" xyz="0 0 0.11"/>
      <geometry>
        <box size="0.06 0.06 0.22"/>
      </geometry>
    </collision>
    <inertial>
      <origin rpy="0 0 0" xyz="0 0 0"/>
      <mass value="1.0025316455696202e-07"/>
      <inertia ixx="4.344303797468354e-10" ixy="0" ixz="0" iyy="4.344303797468354e-10" iyz="0" izz="6.015189873417721e-11"/>
    </inertial>
  </link>
  <link name="third_arm">
    <visual>
      <origin rpy="0 0 0" xyz="0 0 0.08"/>
      <geometry>
        <box size="0.06 0.06 0.16"/>
      </geometry>
      <material name="blue"/>
    </visual>
    <collision>
      <origin rpy="0 0 0" xyz="0 0 0.08"/>
      <geometry>
        <box size="0.06 0.06 0.16"/>
      </geometry>
    </collision>
    <inertial>
      <origin rpy="0 0 0" xyz="0 0 0"/>
      <mass value="7.291139240506328e-08"/>
      <inertia ixx="1.7741772151898732e-10" ixy="0" ixz="0" iyy="1.7741772151898732e-10" iyz="0" izz="4.374683544303797e-11"/>
    </inertial>
  </link>
  <link name="waist_link">
    <visual>
      <origin rpy="0 0 0" xyz="0 0 0"/>
      <geometry>
        <cylinder length="0.08" radius="0.125"/>
      </geometry>
      <material name="green"/>
    </visual>
    <collision>
      <origin rpy="0 0 0" xyz="0 0 0"/>
      <geometry>
        <cylinder length="0.08" radius="0.125"/>
      </geometry>
    </collision>
    <inertial>
      <origin rpy="0 0 0" xyz="0 0 0"/>
      <mass value="4.970727848101267e-07"/>
      <inertia ixx="9.1233567378692e-10" ixy="0" ixz="0" iyy="9.1233567378692e-10" iyz="0" izz="6.472301885548525e-10"/>
    </inertial>
  </link>
  <link name="shoulder_link">
    <visual>
      <origin rpy="0 1.5707 1.5707" xyz="0 0 0"/>
      <geometry>
        <cylinder length="0.1" radius="0.04"/>
      </geometry>
      <material name="green"/>
    </visual>
    <collision>
      <origin rpy="0 1.5707 1.5707" xyz="0 0 0"/>
      <geometry>
        <cylinder length="0.1" radius="0.04"/>
      </geometry>
    </collision>
    <inertial>
      <origin rpy="0 0 0" xyz="0 0 0"/>
      <mass value="6.362531645569622e-08"/>
      <inertia ixx="6.150447257383969e-11" ixy="0" ixz="0" iyy="6.150447257383969e-11" iyz="0" izz="8.483375527426163e-12"/>
    </inertial>
  </link>
  <link name="elbow_link">
    <visual>
      <origin rpy="0 1.5707 1.5707" xyz="0 0 0"/>
      <geometry>
        <cylinder length="0.1" radius="0.04"/>
      </geometry>
      <material name="green"/>
    </visual>
    <collision>
      <origin rpy="0 1.5707 1.5707" xyz="0 0 0"/>
      <geometry>
        <cylinder length="0.1" radius="0.04"/>
      </geometry>
    </collision>
    <inertial>
      <origin rpy="0 0 0" xyz="0 0 0"/>
      <mass value="6.362531645569622e-08"/>
      <inertia ixx="6.150447257383969e-11" ixy="0" ixz="0" iyy="6.150447257383969e-11" iyz="0" izz="8.483375527426163e-12"/>
    </inertial>
  </link>
  <link name="wrist_link">
    <visual>
      <origin rpy="0 1.5707 1.5707" xyz="0 0 0"/>
      <geometry>
        <cylinder length="0.1" radius="0.04"/>
      </geometry>
      <material name="green"/>
    </visual>
    <collision>
      <origin rpy="0 1.5707 1.5707" xyz="0 0 0"/>
      <geometry>
        <cylinder length="0.1" radius="0.04"/>
      </geometry>
    </collision>
    <inertial>
      <origin rpy="0 0 0" xyz="0 0 0"/>
      <mass value="6.362531645569622e-08"/>
      <inertia ixx="6.150447257383969e-11" ixy="0" ixz="0" iyy="6.150447257383969e-11" iyz="0" izz="8.483375527426163e-12"/>
    </inertial>
  </link>
  <link name="base_link">
    </link>
  <joint name="base_link_joint" type="fixed">
    <origin rpy="0 0 0" xyz="0 0 0"/>
    <parent link="base_link"/>
    <child link="robot_stand"/>
  </joint>
  <joint name="waist_stand_robot_joint" type="continuous">
    <origin rpy="0 0 0" xyz="0 0 0.38999999999999996"/>
    <child link="waist_link"/>
    <parent link="robot_stand"/>
    <axis rpy="0 0 0" xyz="0 0 1"/>
    <limit effort="10000" velocity="1000"/>
    <joint_properties damping="1.0" friction="1.0"/>
  </joint>
  <joint name="shoulder_waist_joint" type="continuous">
    <origin rpy="0 0 0" xyz="0 0 0.08"/>
    <child link="shoulder_link"/>
    <parent link="waist_link"/>
    <axis rpy="0 0 0" xyz="0 1 0"/>
    <limit effort="10000" velocity="1000"/>
    <joint_properties damping="1.0" friction="1.0"/>
  </joint>
  <joint name="first_arm_shoulder_joint" type="fixed">
    <origin rpy="0 0 0" xyz="0 0 0.04"/>
    <parent link="shoulder_link"/>
    <child link="first_arm"/>
  </joint>
  <joint name="elbow_first_arm_joint" type="continuous">
    <origin rpy="0 0 0" xyz="0 0 0.36"/>
    <child link="elbow_link"/>
    <parent link="first_arm"/>
    <axis rpy="0 0 0" xyz="0 1 0"/>
    <limit effort="10000" velocity="1000"/>
    <joint_properties damping="1.0" friction="1.0"/>
  </joint>
  <joint name="second_arm_elbow_joint" type="fixed">
    <origin rpy="0 0 0" xyz="0 0 0.04"/>
    <parent link="elbow_link"/>
    <child link="second_arm"/>
  </joint>
  <joint name="wrist_second_arm_joint" type="continuous">
    <origin rpy="0 0 0" xyz="0 0 0.26"/>
    <child link="wrist_link"/>
    <parent link="second_arm"/>
    <axis rpy="0 0 0" xyz="0 1 0"/>
    <limit effort="10000" velocity="1000"/>
    <joint_properties damping="1.0" friction="1.0"/>
  </joint>
  <joint name="third_arm_wrist_joint" type="fixed">
    <origin rpy="0 0 0" xyz="0 0 0.04"/>
    <parent link="wrist_link"/>
    <child link="third_arm"/>
  </joint>
</robot>
